<?xml version="1.0" ?>
<!-- =================================================================================== -->
<!-- |    This document was autogenerated by xacro from float1.urdf.xacro              | -->
<!-- |    EDITING THIS FILE BY HAND IS NOT RECOMMENDED                                 | -->
<!-- =================================================================================== -->
<robot name="float2">
  
  <material name="white">
    <color rgba="1 1 1 0.5"/>
  </material>
  <material name="red">
    <color rgba="1 0 0 1"/>
  </material>
  <material name="orange">
    <color rgba="1 0.3 0.1 1"/>
  </material>
  <material name="blue">
    <color rgba="0.2 0.2 1 1"/>
  </material>
  <material name="black">
    <color rgba="0 0 0 1"/>
  </material>
  <material name="grey">
    <color rgba="0.5 0.5 0.5 1"/>
  </material>

  <link name="base_footprint"/>
  <link name="chassis">
    <visual>
      <geometry>
        <box size="1 1 0.4"/>
      </geometry>
      <origin xyz="0 0 0"/>
      <material name="white"/>
    </visual>
    <collision>
      <geometry>
        <box size="1 1 0.4"/>
      </geometry>
      <origin xyz="0 0 0"/>
    </collision>
    <inertial>
      <origin rpy="0 0 0" xyz="0.0 0 0"/>
      <mass value="1"/>
      <inertia ixx="0.09666666666666668" ixy="0.0" ixz="0.0" iyy="0.09666666666666668" iyz="0.0" izz="0.16666666666666666"/>
    </inertial>
  </link>
  <joint name="base_joint" type="fixed">
    <parent link="base_footprint"/>
    <child link="chassis"/>
    <origin rpy="0 0 0" xyz="0 0 0.2"/>
  </joint>
  <link name="arm_base">
    <visual>
      <geometry>
        <cylinder length="0.1" radius="0.2"/>
      </geometry>
      <origin xyz="0 0 0"/>
      <material name="blue"/>
    </visual>
    <collision>
      <geometry>
        <cylinder length="0.1" radius="0.2"/>
      </geometry>
      <origin xyz="0 0 0"/>
    </collision>
    <inertial>
      <origin rpy="0 0 0" xyz="0.0 0 0"/>
      <mass value="0.5"/>
      <inertia ixx="0.005416666666666668" ixy="0.0" ixz="0.0" iyy="0.005416666666666668" iyz="0.0" izz="0.010000000000000002"/>
    </inertial>
  </link>
  <joint name="base_to_arm" type="continuous">
    <parent link="chassis"/>
    <child link="arm_base"/>
    <axis xyz="0 0 1"/>
    <origin xyz="0 0 0.25"/>
  </joint>
  <joint name="arm_joint1" type="fixed">
    <parent link="arm_base"/>
    <child link="arm_base_link"/>
    <origin xyz="0 0 0.05"/>
  </joint>
  <link name="arm_base_link">
    <inertial>
      <origin rpy="0 0 0" xyz="-1.058E-07 0.045195 -0.00033047"/>
      <mass value="0.19319"/>
      <inertia ixx="0.00016201" ixy="-1.0938E-11" ixz="-2.2636E-11" iyy="5.2247E-05" iyz="3.4329E-06" izz="0.00016791"/>
    </inertial>
    <visual>
      <origin rpy="0 0 0" xyz="0 0 0"/>
      <geometry>
        <mesh filename="package://float1/meshes/base_link.STL"/>
      </geometry>
      <material name="">
        <color rgba="0.75294 0.75294 0.75294 1"/>
      </material>
    </visual>
    <collision>
      <origin rpy="0 0 0" xyz="0 0 0"/>
      <geometry>
        <mesh filename="meshes/base_link.STL"/>
      </geometry>
    </collision>
  </link>
  <link name="link_2">
    <inertial>
      <origin rpy="0 0 0" xyz="-3.1273E-06 -0.097466 -1.1102E-16"/>
      <mass value="0.51799"/>
      <inertia ixx="0.0014412" ixy="1.5788E-07" ixz="-1.4714E-20" iyy="0.00019901" iyz="-1.6943E-21" izz="0.0014474"/>
    </inertial>
    <visual>
      <origin rpy="0 0 0" xyz="0 0 0"/>
      <geometry>
        <mesh filename="meshes/link_2.STL"/>
      </geometry>
      <material name="">
        <color rgba="0.69804 0.69804 0.69804 1"/>
      </material>
    </visual>
    <collision>
      <origin rpy="0 0 0" xyz="0 0 0"/>
      <geometry>
        <mesh filename="meshes/link_2.STL"/>
      </geometry>
    </collision>
  </link>
  <joint name="joint_2" type="revolute">
    <origin rpy="-3.0921 0 -1.5708" xyz="0 0 0.08625"/>
    <parent link="arm_base_link"/>
    <child link="link_2"/>
    <axis xyz="1 0 0"/>
    <limit effort="1000" lower="0" upper="1.57" velocity="10"/>
  </joint>
  <material name="aluminum">
    <color rgba="0.5 0.5 0.5 1"/>
  </material>
  <material name="plastic">
    <color rgba="0.1 0.1 0.1 1"/>
  </material>
  <!-- camera body, with origin at bottom screw mount -->
  <joint name="camera_joint" type="fixed">
    <origin rpy="0 0 -1.57" xyz="0 -0.19 -0.01"/>
    <parent link="link_2"/>
    <child link="camera_bottom_screw_frame"/>
  </joint>
  <link name="camera_bottom_screw_frame"/>
  <joint name="camera_link_joint" type="fixed">
    <origin rpy="0 0 0" xyz="0.010600000000000002 0.0175 0.0125"/>
    <parent link="camera_bottom_screw_frame"/>
    <child link="camera_link"/>
  </joint>
  <link name="camera_link">
    <visual>
      <!-- the mesh origin is at front plate in between the two infrared camera axes -->
      <origin rpy="1.5707963267948966 0 1.5707963267948966" xyz="0.0043 -0.0175 0"/>
      <geometry>
        <mesh filename="meshes/d435.dae"/>
      </geometry>
    </visual>
    <collision>
      <origin rpy="0 0 0" xyz="0 -0.0175 0"/>
      <geometry>
        <box size="0.02505 0.09 0.025"/>
      </geometry>
    </collision>
    <inertial>
      <!-- The following are not reliable values, and should not be used for modeling -->
      <mass value="0.072"/>
      <origin xyz="0 0 0"/>
      <inertia ixx="0.003881243" ixy="0.0" ixz="0.0" iyy="0.000498940" iyz="0.0" izz="0.003879257"/>
    </inertial>
  </link>
</robot>
